Workbook
Name BankList: Dashboard!$A$17:$A$23
Name AccountList: Interest!$D$6:$D$19

Sheet Dashboard
A1: 💰 Digital Bank Savings Tracker
A2: 🏠 Dashboard | C2: ➕ Deposit | E2: 🔄 Transactions | G2: 💼 Balance | I2: 📈 Interest
A3: A live overview of everything in this workbook. Add deposits on the Deposit tab and this page updates automatically.
A4: 🔑 Key Metrics | I4: ="Figures as of "&TEXT(TODAY(),"mmm d, yyyy") -> Figures as of today
A5: Total Current Balance (incl. interest) | E5: =SUM(Balance!$H$6:$H$19) -> 495559.84
A6: Total Deposited (All-Time) | E6: =SUM(Balance!$D$6:$D$19) -> 490000
A7: Interest Earned to Date (auto) | E7: =SUM(Balance!$G$6:$G$19) -> 2559.84
A8: Total Withdrawn | E8: =-SUMIFS(tblTransactions[Amount],tblTransactions[Type],"Withdrawal") -> 2000
A10: 🎯 Personal Goal Tracker
A11: Your Savings Goal Target | E11: 100000
A12: Maya Personal Goal — Current Balance | E12: =IFERROR(VLOOKUP("Maya - Personal Goal",Balance!$C$6:$H$19,6,FALSE),0) -> 25116.67
A13: Progress Toward Goal | E13: =IFERROR(E12/E11,0) -> 0.2512
A15: 🏦 Balance by Bank
A16: Bank | B16: Balance
A17: Maya | B17: =SUMIF(Balance!$A$6:$A$19,A17,Balance!$H$6:$H$19) -> 274565.82
A18: UNO | B18: =SUMIF(Balance!$A$6:$A$19,A18,Balance!$H$6:$H$19) -> 125581.64
A19: Tonik | B19: =SUMIF(Balance!$A$6:$A$19,A19,Balance!$H$6:$H$19) -> 50266.67
A20: Banko | B20: =SUMIF(Balance!$A$6:$A$19,A20,Balance!$H$6:$H$19) -> 15070.02
A21: CIMB | B21: =SUMIF(Balance!$A$6:$A$19,A21,Balance!$H$6:$H$19) -> 10021.45
A22: GoTyme | B22: =SUMIF(Balance!$A$6:$A$19,A22,Balance!$H$6:$H$19) -> 12030
A23: Maribank | B23: =SUMIF(Balance!$A$6:$A$19,A23,Balance!$H$6:$H$19) -> 8024.25
A24: Total | B24: =SUM(B17:B23) -> 495559.84
A27: 📈 Savings Growth by Bank (Cumulative Balance)
A51: 📊 Monthly Interest Earned by Bank
A77: 🗂 Chart Data (auto-calculated — do not edit)
A79: Month | B79: Maya | C79: UNO | D79: Tonik | E79: Banko | F79: CIMB | G79: GoTyme | H79: Maribank | I79: Total Interest
A80: Jan 2026 | B80: =SUMPRODUCT((Interest!$A$6:$A$19=B$79)*Interest!$G$6:$G$19*Interest!$M$6:$M$19^0) -> 273000 | C80: =SUMPRODUCT((Interest!$A$6:$A$19=C$79)*Interest!$G$6:$G$19*Interest!$M$6:$M$19^0) -> 125000 | D80: =SUMPRODUCT((Interest!$A$6:$A$19=D$79)*Interest!$G$6:$G$19*Interest!$M$6:$M$19^0) -> 50000 | E80: =SUMPRODUCT((Interest!$A$6:$A$19=E$79)*Interest!$G$6:$G$19*Interest!$M$6:$M$19^0) -> 15000 | F80: =SUMPRODUCT((Interest!$A$6:$A$19=F$79)*Interest!$G$6:$G$19*Interest!$M$6:$M$19^0) -> 10000 | G80: =SUMPRODUCT((Interest!$A$6:$A$19=G$79)*Interest!$G$6:$G$19*Interest!$M$6:$M$19^0) -> 12000 | H80: =SUMPRODUCT((Interest!$A$6:$A$19=H$79)*Interest!$G$6:$G$19*Interest!$M$6:$M$19^0) -> 8000 | I80: 0
A81: Feb 2026 | B81: =SUMPRODUCT((Interest!$A$6:$A$19=B$79)*Interest!$G$6:$G$19*Interest!$M$6:$M$19^1) -> 274518.28 | C81: =SUMPRODUCT((Interest!$A$6:$A$19=C$79)*Interest!$G$6:$G$19*Interest!$M$6:$M$19^1) -> 125573.02 | D81: =SUMPRODUCT((Interest!$A$6:$A$19=D$79)*Interest!$G$6:$G$19*Interest!$M$6:$M$19^1) -> 50266.67 | E81: =SUMPRODUCT((Interest!$A$6:$A$19=E$79)*Interest!$G$6:$G$19*Interest!$M$6:$M$19^1) -> 15062.63 | F81: =SUMPRODUCT((Interest!$A$6:$A$19=F$79)*Interest!$G$6:$G$19*Interest!$M$6:$M$19^1) -> 10019.18 | G81: =SUMPRODUCT((Interest!$A$6:$A$19=G$79)*Interest!$G$6:$G$19*Interest!$M$6:$M$19^1) -> 12030 | H81: =SUMPRODUCT((Interest!$A$6:$A$19=H$79)*Interest!$G$6:$G$19*Interest!$M$6:$M$19^1) -> 8021.7 | I81: =SUM(B81:H81)-SUM(B80:H80) -> 2491.47
A82: Mar 2026 | B82: =SUMPRODUCT((Interest!$A$6:$A$19=B$79)*Interest!$G$6:$G$19*Interest!$M$6:$M$19^2) -> 276045.47 | C82: =SUMPRODUCT((Interest!$A$6:$A$19=C$79)*Interest!$G$6:$G$19*Interest!$M$6:$M$19^2) -> 126148.75 | D82: =SUMPRODUCT((Interest!$A$6:$A$19=D$79)*Interest!$G$6:$G$19*Interest!$M$6:$M$19^2) -> 50534.89 | E82: =SUMPRODUCT((Interest!$A$6:$A$19=E$79)*Interest!$G$6:$G$19*Interest!$M$6:$M$19^2) -> 15125.51 | F82: =SUMPRODUCT((Interest!$A$6:$A$19=F$79)*Interest!$G$6:$G$19*Interest!$M$6:$M$19^2) -> 10038.41 | G82: =SUMPRODUCT((Interest!$A$6:$A$19=G$79)*Interest!$G$6:$G$19*Interest!$M$6:$M$19^2) -> 12060.07 | H82: =SUMPRODUCT((Interest!$A$6:$A$19=H$79)*Interest!$G$6:$G$19*Interest!$M$6:$M$19^2) -> 8043.45 | I82: =SUM(B82:H82)-SUM(B81:H81) -> 2505.08
A83: Apr 2026 | B83: =SUMPRODUCT((Interest!$A$6:$A$19=B$79)*Interest!$G$6:$G$19*Interest!$M$6:$M$19^3) -> 277581.62 | C83: =SUMPRODUCT((Interest!$A$6:$A$19=C$79)*Interest!$G$6:$G$19*Interest!$M$6:$M$19^3) -> 126727.21 | D83: =SUMPRODUCT((Interest!$A$6:$A$19=D$79)*Interest!$G$6:$G$19*Interest!$M$6:$M$19^3) -> 50804.68 | E83: =SUMPRODUCT((Interest!$A$6:$A$19=E$79)*Interest!$G$6:$G$19*Interest!$M$6:$M$19^3) -> 15188.66 | F83: =SUMPRODUCT((Interest!$A$6:$A$19=F$79)*Interest!$G$6:$G$19*Interest!$M$6:$M$19^3) -> 10057.66 | G83: =SUMPRODUCT((Interest!$A$6:$A$19=G$79)*Interest!$G$6:$G$19*Interest!$M$6:$M$19^3) -> 12090.23 | H83: =SUMPRODUCT((Interest!$A$6:$A$19=H$79)*Interest!$G$6:$G$19*Interest!$M$6:$M$19^3) -> 8065.26 | I83: =SUM(B83:H83)-SUM(B82:H82) -> 2518.77
A84: May 2026 | B84: =SUMPRODUCT((Interest!$A$6:$A$19=B$79)*Interest!$G$6:$G$19*Interest!$M$6:$M$19^4) -> 279126.78 | C84: =SUMPRODUCT((Interest!$A$6:$A$19=C$79)*Interest!$G$6:$G$19*Interest!$M$6:$M$19^4) -> 127308.41 | D84: =SUMPRODUCT((Interest!$A$6:$A$19=D$79)*Interest!$G$6:$G$19*Interest!$M$6:$M$19^4) -> 51076.04 | E84: =SUMPRODUCT((Interest!$A$6:$A$19=E$79)*Interest!$G$6:$G$19*Interest!$M$6:$M$19^4) -> 15252.08 | F84: =SUMPRODUCT((Interest!$A$6:$A$19=F$79)*Interest!$G$6:$G$19*Interest!$M$6:$M$19^4) -> 10076.96 | G84: =SUMPRODUCT((Interest!$A$6:$A$19=G$79)*Interest!$G$6:$G$19*Interest!$M$6:$M$19^4) -> 12120.45 | H84: =SUMPRODUCT((Interest!$A$6:$A$19=H$79)*Interest!$G$6:$G$19*Interest!$M$6:$M$19^4) -> 8087.13 | I84: =SUM(B84:H84)-SUM(B83:H83) -> 2532.53
A85: Jun 2026 | B85: =SUMPRODUCT((Interest!$A$6:$A$19=B$79)*Interest!$G$6:$G$19*Interest!$M$6:$M$19^5) -> 280681.02 | C85: =SUMPRODUCT((Interest!$A$6:$A$19=C$79)*Interest!$G$6:$G$19*Interest!$M$6:$M$19^5) -> 127892.36 | D85: =SUMPRODUCT((Interest!$A$6:$A$19=D$79)*Interest!$G$6:$G$19*Interest!$M$6:$M$19^5) -> 51348.99 | E85: =SUMPRODUCT((Interest!$A$6:$A$19=E$79)*Interest!$G$6:$G$19*Interest!$M$6:$M$19^5) -> 15315.76 | F85: =SUMPRODUCT((Interest!$A$6:$A$19=F$79)*Interest!$G$6:$G$19*Interest!$M$6:$M$19^5) -> 10096.29 | G85: =SUMPRODUCT((Interest!$A$6:$A$19=G$79)*Interest!$G$6:$G$19*Interest!$M$6:$M$19^5) -> 12150.75 | H85: =SUMPRODUCT((Interest!$A$6:$A$19=H$79)*Interest!$G$6:$G$19*Interest!$M$6:$M$19^5) -> 8109.07 | I85: =SUM(B85:H85)-SUM(B84:H84) -> 2546.38
A86: Jul 2026 | B86: =SUMPRODUCT((Interest!$A$6:$A$19=B$79)*Interest!$G$6:$G$19*Interest!$M$6:$M$19^6) -> 282244.39 | C86: =SUMPRODUCT((Interest!$A$6:$A$19=C$79)*Interest!$G$6:$G$19*Interest!$M$6:$M$19^6) -> 128479.08 | D86: =SUMPRODUCT((Interest!$A$6:$A$19=D$79)*Interest!$G$6:$G$19*Interest!$M$6:$M$19^6) -> 51623.53 | E86: =SUMPRODUCT((Interest!$A$6:$A$19=E$79)*Interest!$G$6:$G$19*Interest!$M$6:$M$19^6) -> 15379.7 | F86: =SUMPRODUCT((Interest!$A$6:$A$19=F$79)*Interest!$G$6:$G$19*Interest!$M$6:$M$19^6) -> 10115.66 | G86: =SUMPRODUCT((Interest!$A$6:$A$19=G$79)*Interest!$G$6:$G$19*Interest!$M$6:$M$19^6) -> 12181.13 | H86: =SUMPRODUCT((Interest!$A$6:$A$19=H$79)*Interest!$G$6:$G$19*Interest!$M$6:$M$19^6) -> 8131.06 | I86: =SUM(B86:H86)-SUM(B85:H85) -> 2560.31
A87: Aug 2026 | B87: =SUMPRODUCT((Interest!$A$6:$A$19=B$79)*Interest!$G$6:$G$19*Interest!$M$6:$M$19^7) -> 283816.94 | C87: =SUMPRODUCT((Interest!$A$6:$A$19=C$79)*Interest!$G$6:$G$19*Interest!$M$6:$M$19^7) -> 129068.58 | D87: =SUMPRODUCT((Interest!$A$6:$A$19=D$79)*Interest!$G$6:$G$19*Interest!$M$6:$M$19^7) -> 51899.67 | E87: =SUMPRODUCT((Interest!$A$6:$A$19=E$79)*Interest!$G$6:$G$19*Interest!$M$6:$M$19^7) -> 15443.91 | F87: =SUMPRODUCT((Interest!$A$6:$A$19=F$79)*Interest!$G$6:$G$19*Interest!$M$6:$M$19^7) -> 10135.07 | G87: =SUMPRODUCT((Interest!$A$6:$A$19=G$79)*Interest!$G$6:$G$19*Interest!$M$6:$M$19^7) -> 12211.58 | H87: =SUMPRODUCT((Interest!$A$6:$A$19=H$79)*Interest!$G$6:$G$19*Interest!$M$6:$M$19^7) -> 8153.11 | I87: =SUM(B87:H87)-SUM(B86:H86) -> 2574.32
A88: Sep 2026 | B88: =SUMPRODUCT((Interest!$A$6:$A$19=B$79)*Interest!$G$6:$G$19*Interest!$M$6:$M$19^8) -> 285398.74 | C88: =SUMPRODUCT((Interest!$A$6:$A$19=C$79)*Interest!$G$6:$G$19*Interest!$M$6:$M$19^8) -> 129660.87 | D88: =SUMPRODUCT((Interest!$A$6:$A$19=D$79)*Interest!$G$6:$G$19*Interest!$M$6:$M$19^8) -> 52177.43 | E88: =SUMPRODUCT((Interest!$A$6:$A$19=E$79)*Interest!$G$6:$G$19*Interest!$M$6:$M$19^8) -> 15508.39 | F88: =SUMPRODUCT((Interest!$A$6:$A$19=F$79)*Interest!$G$6:$G$19*Interest!$M$6:$M$19^8) -> 10154.51 | G88: =SUMPRODUCT((Interest!$A$6:$A$19=G$79)*Interest!$G$6:$G$19*Interest!$M$6:$M$19^8) -> 12242.11 | H88: =SUMPRODUCT((Interest!$A$6:$A$19=H$79)*Interest!$G$6:$G$19*Interest!$M$6:$M$19^8) -> 8175.22 | I88: =SUM(B88:H88)-SUM(B87:H87) -> 2588.41
A89: Oct 2026 | B89: =SUMPRODUCT((Interest!$A$6:$A$19=B$79)*Interest!$G$6:$G$19*Interest!$M$6:$M$19^9) -> 286989.84 | C89: =SUMPRODUCT((Interest!$A$6:$A$19=C$79)*Interest!$G$6:$G$19*Interest!$M$6:$M$19^9) -> 130255.96 | D89: =SUMPRODUCT((Interest!$A$6:$A$19=D$79)*Interest!$G$6:$G$19*Interest!$M$6:$M$19^9) -> 52456.82 | E89: =SUMPRODUCT((Interest!$A$6:$A$19=E$79)*Interest!$G$6:$G$19*Interest!$M$6:$M$19^9) -> 15573.14 | F89: =SUMPRODUCT((Interest!$A$6:$A$19=F$79)*Interest!$G$6:$G$19*Interest!$M$6:$M$19^9) -> 10173.99 | G89: =SUMPRODUCT((Interest!$A$6:$A$19=G$79)*Interest!$G$6:$G$19*Interest!$M$6:$M$19^9) -> 12272.72 | H89: =SUMPRODUCT((Interest!$A$6:$A$19=H$79)*Interest!$G$6:$G$19*Interest!$M$6:$M$19^9) -> 8197.39 | I89: =SUM(B89:H89)-SUM(B88:H88) -> 2602.59
A90: Nov 2026 | B90: =SUMPRODUCT((Interest!$A$6:$A$19=B$79)*Interest!$G$6:$G$19*Interest!$M$6:$M$19^10) -> 288590.3 | C90: =SUMPRODUCT((Interest!$A$6:$A$19=C$79)*Interest!$G$6:$G$19*Interest!$M$6:$M$19^10) -> 130853.88 | D90: =SUMPRODUCT((Interest!$A$6:$A$19=D$79)*Interest!$G$6:$G$19*Interest!$M$6:$M$19^10) -> 52737.84 | E90: =SUMPRODUCT((Interest!$A$6:$A$19=E$79)*Interest!$G$6:$G$19*Interest!$M$6:$M$19^10) -> 15638.16 | F90: =SUMPRODUCT((Interest!$A$6:$A$19=F$79)*Interest!$G$6:$G$19*Interest!$M$6:$M$19^10) -> 10193.51 | G90: =SUMPRODUCT((Interest!$A$6:$A$19=G$79)*Interest!$G$6:$G$19*Interest!$M$6:$M$19^10) -> 12303.4 | H90: =SUMPRODUCT((Interest!$A$6:$A$19=H$79)*Interest!$G$6:$G$19*Interest!$M$6:$M$19^10) -> 8219.62 | I90: =SUM(B90:H90)-SUM(B89:H89) -> 2616.85
A91: Dec 2026 | B91: =SUMPRODUCT((Interest!$A$6:$A$19=B$79)*Interest!$G$6:$G$19*Interest!$M$6:$M$19^11) -> 290200.18 | C91: =SUMPRODUCT((Interest!$A$6:$A$19=C$79)*Interest!$G$6:$G$19*Interest!$M$6:$M$19^11) -> 131454.63 | D91: =SUMPRODUCT((Interest!$A$6:$A$19=D$79)*Interest!$G$6:$G$19*Interest!$M$6:$M$19^11) -> 53020.5 | E91: =SUMPRODUCT((Interest!$A$6:$A$19=E$79)*Interest!$G$6:$G$19*Interest!$M$6:$M$19^11) -> 15703.45 | F91: =SUMPRODUCT((Interest!$A$6:$A$19=F$79)*Interest!$G$6:$G$19*Interest!$M$6:$M$19^11) -> 10213.06 | G91: =SUMPRODUCT((Interest!$A$6:$A$19=G$79)*Interest!$G$6:$G$19*Interest!$M$6:$M$19^11) -> 12334.16 | H91: =SUMPRODUCT((Interest!$A$6:$A$19=H$79)*Interest!$G$6:$G$19*Interest!$M$6:$M$19^11) -> 8241.91 | I91: =SUM(B91:H91)-SUM(B90:H90) -> 2631.19
A92: Jan 2027 | B92: =SUMPRODUCT((Interest!$A$6:$A$19=B$79)*Interest!$G$6:$G$19*Interest!$M$6:$M$19^12) -> 291819.54 | C92: =SUMPRODUCT((Interest!$A$6:$A$19=C$79)*Interest!$G$6:$G$19*Interest!$M$6:$M$19^12) -> 132058.23 | D92: =SUMPRODUCT((Interest!$A$6:$A$19=D$79)*Interest!$G$6:$G$19*Interest!$M$6:$M$19^12) -> 53304.82 | E92: =SUMPRODUCT((Interest!$A$6:$A$19=E$79)*Interest!$G$6:$G$19*Interest!$M$6:$M$19^12) -> 15769.01 | F92: =SUMPRODUCT((Interest!$A$6:$A$19=F$79)*Interest!$G$6:$G$19*Interest!$M$6:$M$19^12) -> 10232.66 | G92: =SUMPRODUCT((Interest!$A$6:$A$19=G$79)*Interest!$G$6:$G$19*Interest!$M$6:$M$19^12) -> 12364.99 | H92: =SUMPRODUCT((Interest!$A$6:$A$19=H$79)*Interest!$G$6:$G$19*Interest!$M$6:$M$19^12) -> 8264.26 | I92: =SUM(B92:H92)-SUM(B91:H91) -> 2645.62
A93: Feb 2027 | B93: =SUMPRODUCT((Interest!$A$6:$A$19=B$79)*Interest!$G$6:$G$19*Interest!$M$6:$M$19^13) -> 293448.43 | C93: =SUMPRODUCT((Interest!$A$6:$A$19=C$79)*Interest!$G$6:$G$19*Interest!$M$6:$M$19^13) -> 132664.69 | D93: =SUMPRODUCT((Interest!$A$6:$A$19=D$79)*Interest!$G$6:$G$19*Interest!$M$6:$M$19^13) -> 53590.8 | E93: =SUMPRODUCT((Interest!$A$6:$A$19=E$79)*Interest!$G$6:$G$19*Interest!$M$6:$M$19^13) -> 15834.85 | F93: =SUMPRODUCT((Interest!$A$6:$A$19=F$79)*Interest!$G$6:$G$19*Interest!$M$6:$M$19^13) -> 10252.29 | G93: =SUMPRODUCT((Interest!$A$6:$A$19=G$79)*Interest!$G$6:$G$19*Interest!$M$6:$M$19^13) -> 12395.9 | H93: =SUMPRODUCT((Interest!$A$6:$A$19=H$79)*Interest!$G$6:$G$19*Interest!$M$6:$M$19^13) -> 8286.67 | I93: =SUM(B93:H93)-SUM(B92:H92) -> 2660.13
...

Sheet Deposit
A1: 💰 Digital Bank Savings Tracker
A2: 🏠 Dashboard | C2: ➕ Deposit | E2: 🔄 Transactions | G2: 💼 Balance | I2: 📈 Interest
A3: Log every deposit here. Type a new deposit on the next empty row of the table — balances update automatically. Use the filter arrows to search.
A4: ➕ Add / View Deposits (enter new deposits on the next empty row)
A5: Date | B5: Bank | C5: Account | D5: Amount | E5: Notes
A6: 46174 | B6: Maya | C6: Maya - Savings | D6: 50000 | E6: Opening balance (example)
A7: 46174 | B7: Maya | C7: Maya - Time Deposit 1 | D7: 100000 | E7: Opening balance (example)
A8: 46174 | B8: Maya | C8: Maya - Time Deposit 2 | D8: 100000 | E8: Opening balance (example)
A9: 46174 | B9: Maya | C9: Maya - Personal Goal | D9: 25000 | E9: Opening balance (example)
A10: 46174 | B10: UNO | C10: UNO - Digi Savings | D10: 20000 | E10: Opening balance (example)
A11: 46174 | B11: UNO | C11: UNO - Time Deposit 1 | D11: 50000 | E11: Opening balance (example)
A12: 46174 | B12: UNO | C12: UNO - Time Deposit 2 | D12: 50000 | E12: Opening balance (example)
A13: 46174 | B13: Tonik | C13: Tonik - Stash 1 | D13: 10000 | E13: Opening balance (example)
A14: 46174 | B14: Tonik | C14: Tonik - Stash 2 | D14: 10000 | E14: Opening balance (example)
A15: 46174 | B15: Tonik | C15: Tonik - Time Deposit | D15: 30000 | E15: Opening balance (example)
A16: 46174 | B16: Banko | C16: Banko - Savings | D16: 15000 | E16: Opening balance (example)
A17: 46174 | B17: CIMB | C17: CIMB - Savings | D17: 10000 | E17: Opening balance (example)
... A19: 46174 | B19: Maribank | C19: Maribank - Savings | D19: 8000 | E19: Opening balance (example)

Sheet Transactions
A1: 💰 Digital Bank Savings Tracker
A2: 🏠 Dashboard | C2: ➕ Deposit | E2: 🔄 Transactions | G2: 💼 Balance | I2: 📈 Interest
A3: Log money you move here (deposits/withdrawals/transfers) - use negative amounts for money out, and the filter arrows to search. Interest earned is listed automatically further down and is already included in your Current Balance - do not edit it.
A4: 🔄 Transaction Log (money you move — use the filters)
A5: Date | B5: Type | C5: Bank | D5: Account | E5: Amount | F5: Notes
A6: 46188 | B6: Withdrawal | C6: Maya | D6: Maya - Savings | E6: -2000 | F6: ATM withdrawal (example)
A7: 46198 | B7: Transfer | C7: UNO | D7: UNO - Digi Savings | E7: 5000 | F7: Transfer in (example)
A47: 🪙 Interest Earned (auto-posted — do not edit)
A48: Date | B48: Type | C48: Bank | D48: Account | E48: Amount | F48: Notes
A49: =TODAY() -> 46208 | B49: Interest | C49: Maya | D49: Maya - Savings | E49: =IFERROR(VLOOKUP(D49,Interest!$D$6:$Q$19,13,FALSE),0) -> 449.15 | F49: Interest earned to date
A50: =TODAY() -> 46208 | B50: Interest | C50: Maya | D50: Maya - Time Deposit 1 | E50: =IFERROR(VLOOKUP(D50,Interest!$D$6:$Q$19,13,FALSE),0) -> 500 | F50: Interest earned to date
A51: =TODAY() -> 46208 | B51: Interest | C51: Maya | D51: Maya - Time Deposit 2 | E51: =IFERROR(VLOOKUP(D51,Interest!$D$6:$Q$19,13,FALSE),0) -> 500 | F51: Interest earned to date
A52: =TODAY() -> 46208 | B52: Interest | C52: Maya | D52: Maya - Personal Goal | E52: =IFERROR(VLOOKUP(D52,Interest!$D$6:$Q$19,13,FALSE),0) -> 116.67 | F52: Interest earned to date
A53: =TODAY() -> 46208 | B53: Interest | C53: UNO | D53: UNO - Digi Savings | E53: =IFERROR(VLOOKUP(D53,Interest!$D$6:$Q$19,13,FALSE),0) -> 81.64 | F53: Interest earned to date
A54: =TODAY() -> 46208 | B54: Interest | C54: UNO | D54: UNO - Time Deposit 1 | E54: =IFERROR(VLOOKUP(D54,Interest!$D$6:$Q$19,13,FALSE),0) -> 250 | F54: Interest earned to date
A55: =TODAY() -> 46208 | B55: Interest | C55: UNO | D55: UNO - Time Deposit 2 | E55: =IFERROR(VLOOKUP(D55,Interest!$D$6:$Q$19,13,FALSE),0) -> 250 | F55: Interest earned to date
A56: =TODAY() -> 46208 | B56: Interest | C56: Tonik | D56: Tonik - Stash 1 | E56: =IFERROR(VLOOKUP(D56,Interest!$D$6:$Q$19,13,FALSE),0) -> 33.33 | F56: Interest earned to date
A57: =TODAY() -> 46208 | B57: Interest | C57: Tonik | D57: Tonik - Stash 2 | E57: =IFERROR(VLOOKUP(D57,Interest!$D$6:$Q$19,13,FALSE),0) -> 33.33 | F57: Interest earned to date
A58: =TODAY() -> 46208 | B58: Interest | C58: Tonik | D58: Tonik - Time Deposit | E58: =IFERROR(VLOOKUP(D58,Interest!$D$6:$Q$19,13,FALSE),0) -> 200 | F58: Interest earned to date
A59: =TODAY() -> 46208 | B59: Interest | C59: Banko | D59: Banko - Savings | E59: =IFERROR(VLOOKUP(D59,Interest!$D$6:$Q$19,13,FALSE),0) -> 70.02 | F59: Interest earned to date
A60: =TODAY() -> 46208 | B60: Interest | C60: CIMB | D60: CIMB - Savings | E60: =IFERROR(VLOOKUP(D60,Interest!$D$6:$Q$19,13,FALSE),0) -> 21.45 | F60: Interest earned to date
... A62: =TODAY() -> 46208 | B62: Interest | C62: Maribank | D62: Maribank - Savings | E62: =IFERROR(VLOOKUP(D62,Interest!$D$6:$Q$19,13,FALSE),0) -> 24.25 | F62: Interest earned to date
D63: Total interest | E63: =SUM(E49:E62) -> 2559.84

Sheet Balance
A1: 💰 Digital Bank Savings Tracker
A2: 🏠 Dashboard | C2: ➕ Deposit | E2: 🔄 Transactions | G2: 💼 Balance | I2: 📈 Interest
A3: Current Balance = Principal (Deposits + Net Transactions) + Interest Earned. Interest is posted automatically on the Transactions tab and grows each day/month, so Current Balance rises on its own.
A4: 💼 Balances by Account
A5: Bank | B5: Account | C5: Account Label | D5: Deposits | E5: Net Transactions | F5: Principal | G5: Interest Earned | H5: Current Balance | I5: Interest (1 Yr) | J5: Proj. Balance (1 Yr)
A6: Maya | B6: Savings | C6: Maya - Savings | D6: =SUMIFS(Deposit!$D$6:$D$205,Deposit!$C$6:$C$205,C6) -> 50000 | E6: =SUMIFS(tblTransactions[Amount],tblTransactions[Account],C6) -> -2000 | F6: =D6+E6 -> 48000 | G6: =IFERROR(VLOOKUP(C6,Interest!$D$6:$Q$19,13,FALSE),0) -> 449.15 | H6: =IFERROR(VLOOKUP(C6,Interest!$D$6:$Q$19,14,FALSE),0) -> 48449.15 | I6: =IFERROR(VLOOKUP(C6,Interest!$D$6:$L$19,9,FALSE),0) -> 5047.48 | J6: =F6+I6 -> 53047.48
A7: Maya | B7: Time Deposit 1 | C7: Maya - Time Deposit 1 | D7: =SUMIFS(Deposit!$D$6:$D$205,Deposit!$C$6:$C$205,C7) -> 100000 | E7: =SUMIFS(tblTransactions[Amount],tblTransactions[Account],C7) -> 0 | F7: =D7+E7 -> 100000 | G7: =IFERROR(VLOOKUP(C7,Interest!$D$6:$Q$19,13,FALSE),0) -> 500 | H7: =IFERROR(VLOOKUP(C7,Interest!$D$6:$Q$19,14,FALSE),0) -> 100500 | I7: =IFERROR(VLOOKUP(C7,Interest!$D$6:$L$19,9,FALSE),0) -> 6167.78 | J7: =F7+I7 -> 106167.78
A8: Maya | B8: Time Deposit 2 | C8: Maya - Time Deposit 2 | D8: =SUMIFS(Deposit!$D$6:$D$205,Deposit!$C$6:$C$205,C8) -> 100000 | E8: =SUMIFS(tblTransactions[Amount],tblTransactions[Account],C8) -> 0 | F8: =D8+E8 -> 100000 | G8: =IFERROR(VLOOKUP(C8,Interest!$D$6:$Q$19,13,FALSE),0) -> 500 | H8: =IFERROR(VLOOKUP(C8,Interest!$D$6:$Q$19,14,FALSE),0) -> 100500 | I8: =IFERROR(VLOOKUP(C8,Interest!$D$6:$L$19,9,FALSE),0) -> 6167.78 | J8: =F8+I8 -> 106167.78
A9: Maya | B9: Personal Goal | C9: Maya - Personal Goal | D9: =SUMIFS(Deposit!$D$6:$D$205,Deposit!$C$6:$C$205,C9) -> 25000 | E9: =SUMIFS(tblTransactions[Amount],tblTransactions[Account],C9) -> 0 | F9: =D9+E9 -> 25000 | G9: =IFERROR(VLOOKUP(C9,Interest!$D$6:$Q$19,13,FALSE),0) -> 116.67 | H9: =IFERROR(VLOOKUP(C9,Interest!$D$6:$Q$19,14,FALSE),0) -> 25116.67 | I9: =IFERROR(VLOOKUP(C9,Interest!$D$6:$L$19,9,FALSE),0) -> 1436.5 | J9: =F9+I9 -> 26436.5
A10: UNO | B10: Digi Savings | C10: UNO - Digi Savings | D10: =SUMIFS(Deposit!$D$6:$D$205,Deposit!$C$6:$C$205,C10) -> 20000 | E10: =SUMIFS(tblTransactions[Amount],tblTransactions[Account],C10) -> 5000 | F10: =D10+E10 -> 25000 | G10: =IFERROR(VLOOKUP(C10,Interest!$D$6:$Q$19,13,FALSE),0) -> 81.64 | H10: =IFERROR(VLOOKUP(C10,Interest!$D$6:$Q$19,14,FALSE),0) -> 25081.64 | I10: =IFERROR(VLOOKUP(C10,Interest!$D$6:$L$19,9,FALSE),0) -> 890.45 | J10: =F10+I10 -> 25890.45
A11: UNO | B11: Time Deposit 1 | C11: UNO - Time Deposit 1 | D11: =SUMIFS(Deposit!$D$6:$D$205,Deposit!$C$6:$C$205,C11) -> 50000 | E11: =SUMIFS(tblTransactions[Amount],tblTransactions[Account],C11) -> 0 | F11: =D11+E11 -> 50000 | G11: =IFERROR(VLOOKUP(C11,Interest!$D$6:$Q$19,13,FALSE),0) -> 250 | H11: =IFERROR(VLOOKUP(C11,Interest!$D$6:$Q$19,14,FALSE),0) -> 50250 | I11: =IFERROR(VLOOKUP(C11,Interest!$D$6:$L$19,9,FALSE),0) -> 3083.89 | J11: =F11+I11 -> 53083.89
A12: UNO | B12: Time Deposit 2 | C12: UNO - Time Deposit 2 | D12: =SUMIFS(Deposit!$D$6:$D$205,Deposit!$C$6:$C$205,C12) -> 50000 | E12: =SUMIFS(tblTransactions[Amount],tblTransactions[Account],C12) -> 0 | F12: =D12+E12 -> 50000 | G12: =IFERROR(VLOOKUP(C12,Interest!$D$6:$Q$19,13,FALSE),0) -> 250 | H12: =IFERROR(VLOOKUP(C12,Interest!$D$6:$Q$19,14,FALSE),0) -> 50250 | I12: =IFERROR(VLOOKUP(C12,Interest!$D$6:$L$19,9,FALSE),0) -> 3083.89 | J12: =F12+I12 -> 53083.89
A13: Tonik | B13: Stash 1 | C13: Tonik - Stash 1 | D13: =SUMIFS(Deposit!$D$6:$D$205,Deposit!$C$6:$C$205,C13) -> 10000 | E13: =SUMIFS(tblTransactions[Amount],tblTransactions[Account],C13) -> 0 | F13: =D13+E13 -> 10000 | G13: =IFERROR(VLOOKUP(C13,Interest!$D$6:$Q$19,13,FALSE),0) -> 33.33 | H13: =IFERROR(VLOOKUP(C13,Interest!$D$6:$Q$19,14,FALSE),0) -> 10033.33 | I13: =IFERROR(VLOOKUP(C13,Interest!$D$6:$L$19,9,FALSE),0) -> 407.42 | J13: =F13+I13 -> 10407.42
A14: Tonik | B14: Stash 2 | C14: Tonik - Stash 2 | D14: =SUMIFS(Deposit!$D$6:$D$205,Deposit!$C$6:$C$205,C14) -> 10000 | E14: =SUMIFS(tblTransactions[Amount],tblTransactions[Account],C14) -> 0 | F14: =D14+E14 -> 10000 | G14: =IFERROR(VLOOKUP(C14,Interest!$D$6:$Q$19,13,FALSE),0) -> 33.33 | H14: =IFERROR(VLOOKUP(C14,Interest!$D$6:$Q$19,14,FALSE),0) -> 10033.33 | I14: =IFERROR(VLOOKUP(C14,Interest!$D$6:$L$19,9,FALSE),0) -> 407.42 | J14: =F14+I14 -> 10407.42
A15: Tonik | B15: Time Deposit | C15: Tonik - Time Deposit | D15: =SUMIFS(Deposit!$D$6:$D$205,Deposit!$C$6:$C$205,C15) -> 30000 | E15: =SUMIFS(tblTransactions[Amount],tblTransactions[Account],C15) -> 0 | F15: =D15+E15 -> 30000 | G15: =IFERROR(VLOOKUP(C15,Interest!$D$6:$Q$19,13,FALSE),0) -> 200 | H15: =IFERROR(VLOOKUP(C15,Interest!$D$6:$Q$19,14,FALSE),0) -> 30200 | I15: =IFERROR(VLOOKUP(C15,Interest!$D$6:$L$19,9,FALSE),0) -> 2489.99 | J15: =F15+I15 -> 32489.99
A16: Banko | B16: Savings | C16: Banko - Savings | D16: =SUMIFS(Deposit!$D$6:$D$205,Deposit!$C$6:$C$205,C16) -> 15000 | E16: =SUMIFS(tblTransactions[Amount],tblTransactions[Account],C16) -> 0 | F16: =D16+E16 -> 15000 | G16: =IFERROR(VLOOKUP(C16,Interest!$D$6:$Q$19,13,FALSE),0) -> 70.02 | H16: =IFERROR(VLOOKUP(C16,Interest!$D$6:$Q$19,14,FALSE),0) -> 15070.02 | I16: =IFERROR(VLOOKUP(C16,Interest!$D$6:$L$19,9,FALSE),0) -> 769.01 | J16: =F16+I16 -> 15769.01
A17: CIMB | B17: Savings | C17: CIMB - Savings | D17: =SUMIFS(Deposit!$D$6:$D$205,Deposit!$C$6:$C$205,C17) -> 10000 | E17: =SUMIFS(tblTransactions[Amount],tblTransactions[Account],C17) -> 0 | F17: =D17+E17 -> 10000 | G17: =IFERROR(VLOOKUP(C17,Interest!$D$6:$Q$19,13,FALSE),0) -> 21.45 | H17: =IFERROR(VLOOKUP(C17,Interest!$D$6:$Q$19,14,FALSE),0) -> 10021.45 | I17: =IFERROR(VLOOKUP(C17,Interest!$D$6:$L$19,9,FALSE),0) -> 232.66 | J17: =F17+I17 -> 10232.66
... A19: Maribank | B19: Savings | C19: Maribank - Savings | D19: =SUMIFS(Deposit!$D$6:$D$205,Deposit!$C$6:$C$205,C19) -> 8000 | E19: =SUMIFS(tblTransactions[Amount],tblTransactions[Account],C19) -> 0 | F19: =D19+E19 -> 8000 | G19: =IFERROR(VLOOKUP(C19,Interest!$D$6:$Q$19,13,FALSE),0) -> 24.25 | H19: =IFERROR(VLOOKUP(C19,Interest!$D$6:$Q$19,14,FALSE),0) -> 8024.25 | I19: =IFERROR(VLOOKUP(C19,Interest!$D$6:$L$19,9,FALSE),0) -> 264.26 | J19: =F19+I19 -> 8264.26
A20: TOTAL | D20: =SUM(D6:D19) -> 490000 | E20: =SUM(E6:E19) -> 3000 | F20: =SUM(F6:F19) -> 493000 | G20: =SUM(G6:G19) -> 2559.84 | H20: =SUM(H6:H19) -> 495559.84 | I20: =SUM(I6:I19) -> 30813.51 | J20: =SUM(J6:J19) -> 523813.51

Sheet Interest
A1: 💰 Digital Bank Savings Tracker
A2: 🏠 Dashboard | C2: ➕ Deposit | E2: 🔄 Transactions | G2: 💼 Balance | I2: 📈 Interest
A3: Interest auto-calculates and GROWS ON ITS OWN. 'Balance Today' accrues from the yellow 'Interest Start' date up to TODAY() every time you open the file - daily accounts step up each day, monthly accounts each month. Interest Start is pre-filled with your first deposit date; edit it if an account started elsewhere. Maya Savings = 10%.
A4: 📈 Interest Rates, Earnings & Live Balance
A5: Bank | B5: Account | C5: Account Type | D5: Account Label | E5: Annual Rate | F5: Frequency | G5: Current Balance | H5: Periodic Rate | I5: Interest / Period | J5: Periods / Yr | K5: Proj. Balance (1 Yr) | L5: Interest (1 Yr) | M5: Monthly Factor | N5: Interest Start | O5: Periods Elapsed | P5: Interest to Date | Q5: Balance Today
A6: Maya | B6: Savings | C6: Savings | D6: Maya - Savings | E6: 0.1 | F6: Daily | G6: =IFERROR(VLOOKUP(D6,Balance!$C$6:$H$19,4,FALSE),0) -> 48000 | H6: =IF(F6="Daily",E6/365,E6/12) -> 0.00027397 | I6: =G6*H6 -> 13.15 | J6: =IF(F6="Daily",365,12) -> 365 | K6: =G6*(1+H6)^J6 -> 53047.48 | L6: =K6-G6 -> 5047.48 | M6: =IF(F6="Daily",(1+E6/365)^(365/12),1+E6/12) -> 1.008367 | N6: 46174 | O6: =IF(ISNUMBER(N6),IF(F6="Daily",MAX(0,TODAY()-N6),MAX(0,DATEDIF(N6,TODAY(),"m"))),0) -> 34 | P6: =G6*((1+H6)^O6-1) -> 449.15 | Q6: =G6+P6 -> 48449.15
A7: Maya | B7: Time Deposit 1 | C7: Time Deposit | D7: Maya - Time Deposit 1 | E7: 0.06 | F7: Monthly | G7: =IFERROR(VLOOKUP(D7,Balance!$C$6:$H$19,4,FALSE),0) -> 100000 | H7: =IF(F7="Daily",E7/365,E7/12) -> 0.005 | I7: =G7*H7 -> 500 | J7: =IF(F7="Daily",365,12) -> 12 | K7: =G7*(1+H7)^J7 -> 106167.78 | L7: =K7-G7 -> 6167.78 | M7: =IF(F7="Daily",(1+E7/365)^(365/12),1+E7/12) -> 1.005 | N7: 46174 | O7: =IF(ISNUMBER(N7),IF(F7="Daily",MAX(0,TODAY()-N7),MAX(0,DATEDIF(N7,TODAY(),"m"))),0) -> 1 | P7: =G7*((1+H7)^O7-1) -> 500 | Q7: =G7+P7 -> 100500
A8: Maya | B8: Time Deposit 2 | C8: Time Deposit | D8: Maya - Time Deposit 2 | E8: 0.06 | F8: Monthly | G8: =IFERROR(VLOOKUP(D8,Balance!$C$6:$H$19,4,FALSE),0) -> 100000 | H8: =IF(F8="Daily",E8/365,E8/12) -> 0.005 | I8: =G8*H8 -> 500 | J8: =IF(F8="Daily",365,12) -> 12 | K8: =G8*(1+H8)^J8 -> 106167.78 | L8: =K8-G8 -> 6167.78 | M8: =IF(F8="Daily",(1+E8/365)^(365/12),1+E8/12) -> 1.005 | N8: 46174 | O8: =IF(ISNUMBER(N8),IF(F8="Daily",MAX(0,TODAY()-N8),MAX(0,DATEDIF(N8,TODAY(),"m"))),0) -> 1 | P8: =G8*((1+H8)^O8-1) -> 500 | Q8: =G8+P8 -> 100500
A9: Maya | B9: Personal Goal | C9: Goal | D9: Maya - Personal Goal | E9: 0.056 | F9: Monthly | G9: =IFERROR(VLOOKUP(D9,Balance!$C$6:$H$19,4,FALSE),0) -> 25000 | H9: =IF(F9="Daily",E9/365,E9/12) -> 0.00466667 | I9: =G9*H9 -> 116.67 | J9: =IF(F9="Daily",365,12) -> 12 | K9: =G9*(1+H9)^J9 -> 26436.5 | L9: =K9-G9 -> 1436.5 | M9: =IF(F9="Daily",(1+E9/365)^(365/12),1+E9/12) -> 1.0046667 | N9: 46174 | O9: =IF(ISNUMBER(N9),IF(F9="Daily",MAX(0,TODAY()-N9),MAX(0,DATEDIF(N9,TODAY(),"m"))),0) -> 1 | P9: =G9*((1+H9)^O9-1) -> 116.67 | Q9: =G9+P9 -> 25116.67
A10: UNO | B10: Digi Savings | C10: Savings | D10: UNO - Digi Savings | E10: 0.035 | F10: Daily | G10: =IFERROR(VLOOKUP(D10,Balance!$C$6:$H$19,4,FALSE),0) -> 25000 | H10: =IF(F10="Daily",E10/365,E10/12) -> 9.589e-05 | I10: =G10*H10 -> 2.4 | J10: =IF(F10="Daily",365,12) -> 365 | K10: =G10*(1+H10)^J10 -> 25890.45 | L10: =K10-G10 -> 890.45 | M10: =IF(F10="Daily",(1+E10/365)^(365/12),1+E10/12) -> 1.0029208 | N10: 46174 | O10: =IF(ISNUMBER(N10),IF(F10="Daily",MAX(0,TODAY()-N10),MAX(0,DATEDIF(N10,TODAY(),"m"))),0) -> 34 | P10: =G10*((1+H10)^O10-1) -> 81.64 | Q10: =G10+P10 -> 25081.64
A11: UNO | B11: Time Deposit 1 | C11: Time Deposit | D11: UNO - Time Deposit 1 | E11: 0.06 | F11: Monthly | G11: =IFERROR(VLOOKUP(D11,Balance!$C$6:$H$19,4,FALSE),0) -> 50000 | H11: =IF(F11="Daily",E11/365,E11/12) -> 0.005 | I11: =G11*H11 -> 250 | J11: =IF(F11="Daily",365,12) -> 12 | K11: =G11*(1+H11)^J11 -> 53083.89 | L11: =K11-G11 -> 3083.89 | M11: =IF(F11="Daily",(1+E11/365)^(365/12),1+E11/12) -> 1.005 | N11: 46174 | O11: =IF(ISNUMBER(N11),IF(F11="Daily",MAX(0,TODAY()-N11),MAX(0,DATEDIF(N11,TODAY(),"m"))),0) -> 1 | P11: =G11*((1+H11)^O11-1) -> 250 | Q11: =G11+P11 -> 50250
A12: UNO | B12: Time Deposit 2 | C12: Time Deposit | D12: UNO - Time Deposit 2 | E12: 0.06 | F12: Monthly | G12: =IFERROR(VLOOKUP(D12,Balance!$C$6:$H$19,4,FALSE),0) -> 50000 | H12: =IF(F12="Daily",E12/365,E12/12) -> 0.005 | I12: =G12*H12 -> 250 | J12: =IF(F12="Daily",365,12) -> 12 | K12: =G12*(1+H12)^J12 -> 53083.89 | L12: =K12-G12 -> 3083.89 | M12: =IF(F12="Daily",(1+E12/365)^(365/12),1+E12/12) -> 1.005 | N12: 46174 | O12: =IF(ISNUMBER(N12),IF(F12="Daily",MAX(0,TODAY()-N12),MAX(0,DATEDIF(N12,TODAY(),"m"))),0) -> 1 | P12: =G12*((1+H12)^O12-1) -> 250 | Q12: =G12+P12 -> 50250
A13: Tonik | B13: Stash 1 | C13: Savings | D13: Tonik - Stash 1 | E13: 0.04 | F13: Monthly | G13: =IFERROR(VLOOKUP(D13,Balance!$C$6:$H$19,4,FALSE),0) -> 10000 | H13: =IF(F13="Daily",E13/365,E13/12) -> 0.00333333 | I13: =G13*H13 -> 33.33 | J13: =IF(F13="Daily",365,12) -> 12 | K13: =G13*(1+H13)^J13 -> 10407.42 | L13: =K13-G13 -> 407.42 | M13: =IF(F13="Daily",(1+E13/365)^(365/12),1+E13/12) -> 1.0033333 | N13: 46174 | O13: =IF(ISNUMBER(N13),IF(F13="Daily",MAX(0,TODAY()-N13),MAX(0,DATEDIF(N13,TODAY(),"m"))),0) -> 1 | P13: =G13*((1+H13)^O13-1) -> 33.33 | Q13: =G13+P13 -> 10033.33
A14: Tonik | B14: Stash 2 | C14: Savings | D14: Tonik - Stash 2 | E14: 0.04 | F14: Monthly | G14: =IFERROR(VLOOKUP(D14,Balance!$C$6:$H$19,4,FALSE),0) -> 10000 | H14: =IF(F14="Daily",E14/365,E14/12) -> 0.00333333 | I14: =G14*H14 -> 33.33 | J14: =IF(F14="Daily",365,12) -> 12 | K14: =G14*(1+H14)^J14 -> 10407.42 | L14: =K14-G14 -> 407.42 | M14: =IF(F14="Daily",(1+E14/365)^(365/12),1+E14/12) -> 1.0033333 | N14: 46174 | O14: =IF(ISNUMBER(N14),IF(F14="Daily",MAX(0,TODAY()-N14),MAX(0,DATEDIF(N14,TODAY(),"m"))),0) -> 1 | P14: =G14*((1+H14)^O14-1) -> 33.33 | Q14: =G14+P14 -> 10033.33
A15: Tonik | B15: Time Deposit | C15: Time Deposit | D15: Tonik - Time Deposit | E15: 0.08 | F15: Monthly | G15: =IFERROR(VLOOKUP(D15,Balance!$C$6:$H$19,4,FALSE),0) -> 30000 | H15: =IF(F15="Daily",E15/365,E15/12) -> 0.00666667 | I15: =G15*H15 -> 200 | J15: =IF(F15="Daily",365,12) -> 12 | K15: =G15*(1+H15)^J15 -> 32489.99 | L15: =K15-G15 -> 2489.99 | M15: =IF(F15="Daily",(1+E15/365)^(365/12),1+E15/12) -> 1.0066667 | N15: 46174 | O15: =IF(ISNUMBER(N15),IF(F15="Daily",MAX(0,TODAY()-N15),MAX(0,DATEDIF(N15,TODAY(),"m"))),0) -> 1 | P15: =G15*((1+H15)^O15-1) -> 200 | Q15: =G15+P15 -> 30200
A16: Banko | B16: Savings | C16: Savings | D16: Banko - Savings | E16: 0.05 | F16: Daily | G16: =IFERROR(VLOOKUP(D16,Balance!$C$6:$H$19,4,FALSE),0) -> 15000 | H16: =IF(F16="Daily",E16/365,E16/12) -> 0.00013699 | I16: =G16*H16 -> 2.05 | J16: =IF(F16="Daily",365,12) -> 365 | K16: =G16*(1+H16)^J16 -> 15769.01 | L16: =K16-G16 -> 769.01 | M16: =IF(F16="Daily",(1+E16/365)^(365/12),1+E16/12) -> 1.0041751 | N16: 46174 | O16: =IF(ISNUMBER(N16),IF(F16="Daily",MAX(0,TODAY()-N16),MAX(0,DATEDIF(N16,TODAY(),"m"))),0) -> 34 | P16: =G16*((1+H16)^O16-1) -> 70.02 | Q16: =G16+P16 -> 15070.02
A17: CIMB | B17: Savings | C17: Savings | D17: CIMB - Savings | E17: 0.023 | F17: Daily | G17: =IFERROR(VLOOKUP(D17,Balance!$C$6:$H$19,4,FALSE),0) -> 10000 | H17: =IF(F17="Daily",E17/365,E17/12) -> 6.301e-05 | I17: =G17*H17 -> 0.63 | J17: =IF(F17="Daily",365,12) -> 365 | K17: =G17*(1+H17)^J17 -> 10232.66 | L17: =K17-G17 -> 232.66 | M17: =IF(F17="Daily",(1+E17/365)^(365/12),1+E17/12) -> 1.0019184 | N17: 46174 | O17: =IF(ISNUMBER(N17),IF(F17="Daily",MAX(0,TODAY()-N17),MAX(0,DATEDIF(N17,TODAY(),"m"))),0) -> 34 | P17: =G17*((1+H17)^O17-1) -> 21.45 | Q17: =G17+P17 -> 10021.45
... A19: Maribank | B19: Savings | C19: Savings | D19: Maribank - Savings | E19: 0.0325 | F19: Daily | G19: =IFERROR(VLOOKUP(D19,Balance!$C$6:$H$19,4,FALSE),0) -> 8000 | H19: =IF(F19="Daily",E19/365,E19/12) -> 8.904e-05 | I19: =G19*H19 -> 0.71 | J19: =IF(F19="Daily",365,12) -> 365 | K19: =G19*(1+H19)^J19 -> 8264.26 | L19: =K19-G19 -> 264.26 | M19: =IF(F19="Daily",(1+E19/365)^(365/12),1+E19/12) -> 1.0027119 | N19: 46174 | O19: =IF(ISNUMBER(N19),IF(F19="Daily",MAX(0,TODAY()-N19),MAX(0,DATEDIF(N19,TODAY(),"m"))),0) -> 34 | P19: =G19*((1+H19)^O19-1) -> 24.25 | Q19: =G19+P19 -> 8024.25
A20: TOTAL | G20: =SUM(G6:G19) -> 493000 | K20: =SUM(K6:K19) -> 523813.51 | L20: =SUM(L6:L19) -> 30813.51 | P20: =SUM(P6:P19) -> 2559.84 | Q20: =SUM(Q6:Q19) -> 495559.84
